Workbook

Sheet 装置总览
A1: 全球托卡马克 · 装置参数总览
A2: 检索截止 2026-09-09 | 310 条装置／版本／工况记录 | 空白表示未查到；数值性质见“参数口径”；2026-09-14 第二轮新增 B_t（环向场）列
A3: 橙底及†：几何推算值，非实测；推算字段见T列，公式和证据见第二张表。空白为未查到，行数不等于独立装置数。
A5: 国家／地区 | B5: 装置／版本 | C5: R (m) | D5: a (m) | E5: κ | F5: δ | G5: Ip (MA) | H5: B_t (T) | I5: 参数口径 | J5: 状态 | K5: 状态证据年 | L5: 类别 | M5: 已填项数 | N5: 来源编号 | O5: 记录ID | P5: 证据层级 | Q5: 缺失字段 | R5: 机构 | S5: 版本／迁移关系 | T5: 范围分类 | U5: 几何推算字段 | V5: 文献直接报告项数 | W5: 几何推算说明
A6: 中国 | B6: BEST | C6: 3.6 | D6: 1.1 | E6: 1.87 | F6: 0.51 | G6: 7 | H6: 6.15 | I6: 设计参数 | J6: 在建 | K6: 2026-05-01 | L6: 常规 | M6: =6-COUNTBLANK(C6:H6) -> 6 | N6: S015; S016 | O6: AS_best | P6: 仅检索摘要 | R6: ASIPP，合肥 | T6: 常规／球形托卡马克 | V6: 5
A7: 中国 | B7: CFETR（2021混合运行情景） | C7: 7.2 | D7: 2 | E7: 2 | F7: 0.52 | G7: 13.7 | H7: 5 | I7: 设计参数（R7.2m、1GW hybrid scenario） | J7: 设计 | K7: 2022 | L7: 常规 | M7: =6-COUNTBLANK(C7:H7) -> 6 | N7: S001; S061 | O7: AS_cfetr | P7: 全文核验 | R7: 中国联合体 | T7: 常规／球形托卡马克 | V7: 5
A8: 中国 | B8: CT-6 | H8: 2 | I8: 无参数 | J8: 历史装置，现状未核实 | K8: 2018 | L8: 常规 | M8: =6-COUNTBLANK(C8:H8) -> 1 | N8: S027 | O8: AS_ct6 | P8: 仅名录 | Q8: 大半径 R；小半径 a；拉长比 κ；三角度 δ；总等离子体电流 Ip | R8: 中国科学院物理研究所，北京 | S8: CT-6B前身，确切版本关系待核 | T8: 常规／球形托卡马克 | V8: 0
A9: 中国 | B9: CT-6B | C9: 0.45 | D9: 0.125 | E9: 1 | F9: 0 | G9: 0.03 | H9: 0.75 | I9: 文献汇总值，含理想圆形边界几何推算 | J9: 已停运 | K9: 2002 | L9: 常规 | M9: =6-COUNTBLANK(C9:H9) -> 6 | N9: S002; S003 | O9: AS_ct6b | P9: 全文核验 | R9: 中国科学院物理研究所，北京 | T9: 常规／球形托卡马克 | U9: 三角度 δ | V9: 4 | W9: delta: AS_S03已读取历史汇编将本装置明确归为圆形限制器/偏滤器配置；采用圆形等离子体理想边界：δ=0。是名义几何推算，不是逐炮平衡实测；原始装置论文尚待独立复核。
A10: 中国 | B10: EAST | C10: 1.8 | D10: 0.45 | E10: 1.5–2.0 | F10: 0.3–0.6 | G10: 1 | H10: 3.5 | I10: 装置额定参数 | J10: 现状待核实 | K10: 2022 | L10: 常规 | M10: =6-COUNTBLANK(C10:H10) -> 6 | N10: S001; S004 | O10: AS_east | P10: 仅检索摘要 | R10: ASIPP，合肥 | T10: 常规／球形托卡马克 | V10: 5
A11: 中国 | B11: EHL-2（2025平衡V43） | C11: 1.09 | D11: 0.6 | E11: 2.26 | F11: 0.4 | G11: 3 | H11: 3 | I11: 设计参数（V43平衡工况） | J11: 设计 | K11: 2026-09-09 | L11: 球形 | M11: =6-COUNTBLANK(C11:H11) -> 6 | N11: S033; S066 | O11: AS_ehl2 | P11: 全文核验 | R11: ENN, Langfang | T11: 常规／球形托卡马克 | V11: 5
A12: 中国 | B12: EXL-50 | C12: 0.6 | D12: 0.4 | E12: 1.8–2.2 | F12: 0.1–0.4 | G12: 0.5 | H12: 0.45 | I12: 设计参数 | J12: 现状待核实 | K12: 2022 | L12: 球形 | M12: =6-COUNTBLANK(C12:H12) -> 6 | N12: S001; S005; S038 | O12: AS_exl50 | P12: 全文核验 | R12: ENN，新奥，廊坊 | T12: 常规／球形托卡马克 | V12: 5
A13: 中国 | B13: EXL-50U | C13: 0.60–0.80 | E13: 2 | G13: 0.5–1 | H13: 0.6-0.8 | I13: 设计参数 | J13: 运行 | K13: 2025-04 | L13: 球形 | M13: =6-COUNTBLANK(C13:H13) -> 4 | N13: S013 | O13: AS_exl50u | P13: 仅检索摘要 | Q13: 小半径 a；三角度 δ | R13: ENN，新奥，廊坊 | S13: EXL-50升级 | T13: 常规／球形托卡马克 | V13: 3
A14: 中国 | B14: FDS-III | C14: 5.1 | D14: 1.7 | E14: 1.9 | F14: 0.53 | G14: 16 | I14: 设计参数 | J14: 设计 | K14: 2005 | L14: 常规 | M14: =6-COUNTBLANK(C14:H14) -> 5 | N14: S030; S047 | O14: AS_fdsiii | P14: 全文核验 | R14: ASIPP / FDS Team | S14: FDS系列 | T14: 常规／球形托卡马克 | V14: 5
A15: 中国 | B15: FDS-II（2005设计） | C15: 6 | D15: 2 | E15: 1.9 | F15: 0.6 | G15: 15 | H15: 5.9 | I15: 设计参数 | J15: 设计 | K15: 2005 | L15: 常规 | M15: =6-COUNTBLANK(C15:H15) -> 6 | N15: S030 | O15: AS_fdsii | P15: 全文核验 | R15: ASIPP / FDS Team | S15: FDS系列 | T15: 常规／球形托卡马克 | V15: 5
A16: 中国 | B16: FDS-I（2005设计） | C16: 4 | D16: 1 | E16: 1.78 | F16: 0.4 | G16: 6.3 | H16: 6.1 | I16: 设计参数 | J16: 设计 | K16: 2005 | L16: 常规 | M16: =6-COUNTBLANK(C16:H16) -> 6 | N16: S030 | O16: AS_fdsi | P16: 全文核验 | R16: ASIPP / FDS Team | S16: FDS系列 | T16: 常规／球形托卡马克 | V16: 5
A17: 中国 | B17: FDS-ST（2005设计） | C17: 1.4 | D17: 1 | E17: 2.5 | F17: 0.45 | G17: 9.2 | H17: 2.5 | I17: 设计参数 | J17: 设计 | K17: 2005 | L17: 球形 | M17: =6-COUNTBLANK(C17:H17) -> 6 | N17: S030 | O17: AS_fdsst | P17: 全文核验 | R17: ASIPP / FDS Team | S17: FDS系列 | T17: 常规／球形托卡马克 | V17: 5
A18: 中国 | B18: FY-1 | C18: 0.48 | D18: 0.1 | E18: 2.5 | G18: 0.18 | H18: 1 | I18: 文献汇总值，含几何推算 | J18: 历史装置，现状未核实 | K18: 2012汇编 | L18: 常规 | M18: =6-COUNTBLANK(C18:H18) -> 5 | N18: S003 | O18: AS_fy1 | P18: 历史汇编待原文复核 | Q18: 三角度 δ | R18: 机构待核实 | T18: 常规／球形托卡马克 | U18: 拉长比 κ | V18: 3 | W18: kappa: S003 FY-1明确非圆等离子体a=10 cm、b=25 cm；κ=b/a=25/10=2.5，几何换算，非逐炮实测；δ不由非圆推定。
A19: 中国 | B19: HH170 | C19: 1.5 | H19: 21.7 | I19: 设计参数 | J19: 设计 | K19: 2026-09-09 | L19: 常规 | M19: =6-COUNTBLANK(C19:H19) -> 2 | N19: S034 | O19: AS_hh170 | P19: 官方页面核验 | Q19: 小半径 a；拉长比 κ；三角度 δ；总等离子体电流 Ip | R19: Energy Singularity, Shanghai | S19: HH70后续装置 | T19: 常规／球形托卡马克 | V19: 1
A20: 中国 | B20: HH70 | C20: 0.70–0.75 | D20: 0.25–0.31 | H20: 0.6 | I20: 设计参数 | J20: 运行 | K20: 2024-06 | L20: 常规 | M20: =6-COUNTBLANK(C20:H20) -> 3 | N20: S014 | O20: AS_hh70 | P20: 仅检索摘要 | Q20: 拉长比 κ；三角度 δ；总等离子体电流 Ip | R20: 能量奇点，上海 | T20: 常规／球形托卡马克 | V20: 2
A21: 中国 | B21: HL-1 | C21: 1.02 | D21: 0.2 | E21: 1 | F21: 0 | G21: 0.225 | H21: 3 | I21: 文献汇总值，含理想圆形边界几何推算 | J21: 历史装置，现状未核实 | K21: 2012汇编 | L21: 常规 | M21: =6-COUNTBLANK(C21:H21) -> 6 | N21: S003 | O21: AS_hl1 | P21: 历史汇编待原文复核 | R21: SWIP | S21: 后改为HL-1M | T21: 常规／球形托卡马克 | U21: 拉长比 κ；三角度 δ | V21: 3 | W21: kappa: AS_S03已读取历史汇编将本装置明确归为圆形限制器/偏滤器配置；采用圆形等离子体理想边界：κ=b/a=1。是名义几何推算，不是逐炮平衡实测；原始装置论文尚待独立复核。 delta: AS_S03已读取历史汇编将本装置明确归为圆形限制器/偏滤器配置；采用圆形等离子体理想边界：δ=0。是名义几何推算，不是逐炮平衡实测；原始装置论文尚待独立复核。
A22: 中国 | B22: HL-1M | C22: 1.02 | D22: 0.26 | E22: 1 | F22: 0 | G22: 0.35 | H22: 3 | I22: 文献汇总值，含理想边界几何推算 | J22: 已停运 | K22: 2001 | L22: 常规 | M22: =6-COUNTBLANK(C22:H22) -> 6 | N22: S002; S060 | O22: AS_hl1m | P22: 全文核验 | R22: SWIP，成都 | T22: 常规／球形托卡马克 | U22: 三角度 δ | V22: 4 | W22: delta: S060 原文明示圆形等离子体截面；按理想圆边界delta=0推算，非逐炮平衡实测。
A23: 中国 | B23: HL-2A | C23: 1.64 | D23: 0.4 | E23: 1 | F23: 0 | G23: 0.48 | H23: 2.8 | I23: 设计参数（2000基准配置） | J23: 现状待核实 | K23: 2022 | L23: 常规 | M23: =6-COUNTBLANK(C23:H23) -> 6 | N23: S001; S050 | O23: AS_hl2a | P23: 全文核验 | R23: SWIP，成都 | S23: 利用德国ASDEX原磁体和真空室部件 | T23: 常规／球形托卡马克 | V23: 5
A24: 中国 | B24: HL-2M / HL-3（2012设计参数） | C24: 1.78 | D24: 0.65 | E24: 2 | F24: ≥0.5 | G24: 2.5 | H24: 3 | I24: 设计参数 | J24: 运行 | K24: 2026-04-08 | L24: 常规 | M24: =6-COUNTBLANK(C24:H24) -> 6 | N24: S001; S041; S042; S046 | O24: AS_hl2m | P24: 全文核验 | R24: SWIP，成都 | S24: HL-2M后来改称HL-3，非独立再计机器。 | T24: 常规／球形托卡马克 | V24: 5
A25: 中国 | B25: HT-6B | C25: 0.45 | D25: 0.12 | E25: 1 | F25: 0 | G25: 0.04 | H25: 0.75 | I25: 文献汇总值，含理想圆形边界几何推算 | J25: 历史装置，现状未核实 | K25: 2012汇编 | L25: 常规 | M25: =6-COUNTBLANK(C25:H25) -> 6 | N25: S003 | O25: AS_ht6b | P25: 历史汇编待原文复核 | R25: ASIPP，合肥 | S25: 后移交伊朗成为IR-T1 | T25: 常规／球形托卡马克 | U25: 拉长比 κ；三角度 δ | V25: 3 | W25: kappa: AS_S03已读取历史汇编将本装置明确归为圆形限制器/偏滤器配置；采用圆形等离子体理想边界：κ=b/a=1。是名义几何推算，不是逐炮平衡实测；原始装置论文尚待独立复核。 delta: AS_S03已读取历史汇编将本装置明确归为圆形限制器/偏滤器配置；采用圆形等离子体理想边界：δ=0。是名义几何推算，不是逐炮平衡实测；原始装置论文尚待独立复核。
A26: 中国 | B26: HT-6M | C26: 0.65 | D26: 0.2 | E26: 1 | F26: 0 | G26: 0.15 | H26: 1.5 | I26: 文献汇总值，含理想圆形边界几何推算 | J26: 历史装置，现状未核实 | K26: 2005 | L26: 常规 | M26: =6-COUNTBLANK(C26:H26) -> 6 | N26: S002; S018; S003 | O26: AS_ht6m | P26: 全文核验 | R26: ASIPP，合肥 | S26: 后重建为泰国Thailand Tokamak-1（AS_S18），同一迁移谱系。 | T26: 常规／球形托卡马克 | U26: 三角度 δ | V26: 4 | W26: delta: AS_S03已读取历史汇编将本装置明确归为圆形限制器/偏滤器配置；采用圆形等离子体理想边界：δ=0。是名义几何推算，不是逐炮平衡实测；原始装置论文尚待独立复核。
A27: 中国 | B27: HT-7 | C27: 1.22 | D27: 0.35 | E27: 1 | F27: 0 | G27: 0.4 | H27: 3 | I27: 文献汇总值，含理想圆形边界几何推算 | J27: 历史装置，现状未核实 | K27: 2005 | L27: 常规 | M27: =6-COUNTBLANK(C27:H27) -> 6 | N27: S002; S003 | O27: AS_ht7 | P27: 全文核验 | R27: ASIPP，合肥 | T27: 常规／球形托卡马克 | U27: 三角度 δ | V27: 4 | W27: delta: AS_S03已读取历史汇编将本装置明确归为圆形限制器/偏滤器配置；采用圆形等离子体理想边界：δ=0。是名义几何推算，不是逐炮平衡实测；原始装置论文尚待独立复核。
A28: 中国 | B28: J-TEXT | C28: 1.05 | D28: 0.25–0.29 | G28: 0.2 | H28: 2 | I28: 文献汇总值 | J28: 现状待核实 | K28: 2022 | L28: 常规 | M28: =6-COUNTBLANK(C28:H28) -> 4 | N28: S001 | O28: AS_jtext | P28: 全文核验 | Q28: 拉长比 κ；三角度 δ | R28: 华中科技大学，武汉 | S28: 原美国TEXT/TEXT-U迁入 | T28: 常规／球形托卡马克 | V28: 3
A29: 中国 | B29: KT-5 | C29: 0.3 | D29: 0.045 | G29: >0.005 | H29: 0.45 | I29: 实验工况（1987第一阶段） | J29: 历史装置，现状未核实 | K29: 2018 | L29: 常规 | M29: =6-COUNTBLANK(C29:H29) -> 4 | N29: S027; S062 | O29: AS_kt5 | P29: 摘要核验 | Q29: 拉长比 κ；三角度 δ | R29: 中国科学技术大学，合肥 | S29: KT-5C前身，确切版本关系待核 | T29: 常规／球形托卡马克 | V29: 3
A30: 中国 | B30: KT-5C | C30: 0.325 | D30: 0.095 | E30: 1 | F30: 0 | G30: 0.02 | H30: 0.7 | I30: 文献汇总值，含理想圆形边界几何推算 | J30: 历史装置，现状未核实 | K30: 2005 | L30: 常规 | M30: =6-COUNTBLANK(C30:H30) -> 6 | N30: S002; S003 | O30: AS_kt5c | P30: 全文核验 | R30: 中国科学技术大学，合肥 | T30: 常规／球形托卡马克 | U30: 三角度 δ | V30: 4 | W30: delta: AS_S03已读取历史汇编将本装置明确归为圆形限制器/偏滤器配置；采用圆形等离子体理想边界：δ=0。是名义几何推算，不是逐炮平衡实测；原始装置论文尚待独立复核。
A31: 中国 | B31: NTST | C31: 0.87 | D31: 0.56 | E31: 2 | F31: −0.8–0.6 | G31: 1.3 | H31: 1.0 | I31: 设计参数 | J31: 在建 | K31: 2025 | L31: 球形 | M31: =6-COUNTBLANK(C31:H31) -> 6 | N31: S017 | O31: AS_ntst | P31: 全文核验 | R31: Startorus Fusion，西安；清华大学 | S31: 负三角度球形装置 | T31: 常规／球形托卡马克 | V31: 5
A32: 中国 | B32: SUNIST-1 | C32: 0.3 | D32: 0.22 | E32: 1.6 | G32: 0.05 | H32: 0.15 | I32: 文献汇总值 | J32: 现状待核实 | K32: 2005 | L32: 球形 | M32: =6-COUNTBLANK(C32:H32) -> 5 | N32: S002 | O32: AS_sunist | P32: 全文核验 | Q32: 三角度 δ | R32: 清华大学，北京 | T32: 常规／球形托卡马克 | V32: 4
A33: 中国 | B33: SUNIST-2 | C33: 0.53 | D33: 0.33 | E33: 2 | F33: −0.6–0.6 | G33: 0.5 | H33: 0.72 | I33: 装置额定参数 | J33: 运行 | K33: 2023-07 | L33: 球形 | M33: =6-COUNTBLANK(C33:H33) -> 6 | N33: S011; S012; S044 | O33: AS_sunist2 | P33: 全文核验 | R33: 清华大学 / ASIPP / Startorus | S33: SUNIST后继 | T33: 常规／球形托卡马克 | V33: 5
A34: 中国台湾 | B34: FIRST | C34: 0.45 | D34: 0.32 | E34: 2.4 | F34: 0.5 | H34: 0.8 | I34: 设计参数 | J34: 设计 | K34: 2025 | L34: 球形 | M34: =6-COUNTBLANK(C34:H34) -> 5 | N34: S019 | O34: AS_first | P34: 摘要核验 | Q34: 总等离子体电流 Ip | R34: 成功大学 | T34: 常规／球形托卡马克 | V34: 4
A35: 日本 | B35: A-SSTR2 | C35: 6.2 | D35: 1.5 | G35: 12 | H35: 11 | I35: 文献汇总值 | J35: 设计 | K35: 2013 | L35: 常规 | M35: =6-COUNTBLANK(C35:H35) -> 4 | N35: S037 | O35: AS_asstr2 | P35: 仅检索摘要 | Q35: 拉长比 κ；三角度 δ | R35: JAERI / Japanese design team | S35: 日本历史概念 | T35: 常规／球形托卡马克 | V35: 3
A36: 日本 | B36: C-TOKASTAR | C36: 约0.02 | H36: 0.01 | I36: 实验装置尺寸（2009版本） | J36: 历史装置，现状未核实 | K36: 2022 | L36: 混合配置 | M36: =6-COUNTBLANK(C36:H36) -> 2 | N36: S001; S056 | O36: AS_ctokastar | P36: 全文核验 | Q36: 小半径 a；拉长比 κ；三角度 δ；总等离子体电流 Ip | R36: 名古屋大学 | S36: TOKASTAR-2前序；托卡马克模式运行证据待核 | T36: 候选：托卡马克模式待核 | V36: 1
A37: 日本 | B37: CPD（Compact PWI experimental Device） | C37: 0.3 | D37: 0.2 | G37: 0.15 | H37: 0.3 | I37: 装置额定参数 | J37: 历史装置，现状未核实 | K37: 2007 | L37: 球形 | M37: =6-COUNTBLANK(C37:H37) -> 4 | N37: S029 | O37: AS_cpd_jp | P37: 全文核验 | Q37: 拉长比 κ；三角度 δ | R37: RIAM, Kyushu University | T37: 常规／球形托卡马克 | V37: 3
A38: 日本 | B38: CREST | C38: 5.4 | D38: 1.5882353 | E38: 2 | F38: 0.5 | G38: 12 | H38: 5.4 | I38: 设计参数，含几何推算 | J38: 设计 | K38: 2013 | L38: 常规 | M38: =6-COUNTBLANK(C38:H38) -> 6 | N38: S037; S049 | O38: AS_crest | P38: 全文核验 | R38: CRIEPI / Japanese design team | S38: 日本历史概念 | T38: 常规／球形托卡马克 | U38: 小半径 a | V38: 4 | W38: a_m: S049 slide 7：R=5.4 m，A=3.4；a=R/A=1.5882352941 m，几何换算，非实测。
A39: 日本 | B39: CSTN-AC | C39: 0.4 | D39: 0.1 | E39: 1 | F39: 0 | G39: 0.001 | H39: 0.12 | I39: 文献汇总值，含理想圆形边界几何推算 | J39: 历史装置，现状未核实 | K39: 2012汇编 | L39: 常规 | M39: =6-COUNTBLANK(C39:H39) -> 6 | N39: S003 | O39: AS_cstnac | P39: 历史汇编待原文复核 | R39: 名古屋大学 | S39: 后升级CSTN-IV | T39: 常规／球形托卡马克 | U39: 拉长比 κ；三角度 δ | V39: 3 | W39: kappa: AS_S03已读取历史汇编将本装置明确归为圆形限制器/偏滤器配置；采用圆形等离子体理想边界：κ=b/a=1。是名义几何推算，不是逐炮平衡实测；原始装置论文尚待独立复核。 delta: AS_S03已读取历史汇编将本装置明确归为圆形限制器/偏滤器配置；采用圆形等离子体理想边界：δ=0。是名义几何推算，不是逐炮平衡实测；原始装置论文尚待独立复核。
A40: 日本 | B40: CSTN-I | C40: 0.3 | D40: 0.04 | E40: 1 | F40: 0 | H40: 0.2 | I40: 文献汇总值，含理想圆形边界几何推算 | J40: 历史装置，现状未核实 | K40: 2012汇编 | L40: 常规 | M40: =6-COUNTBLANK(C40:H40) -> 5 | N40: S003 | O40: AS_cstn1 | P40: 历史汇编待原文复核 | Q40: 总等离子体电流 Ip | R40: 名古屋大学 | T40: 常规／球形托卡马克 | U40: 拉长比 κ；三角度 δ | V40: 2 | W40: kappa: AS_S03已读取历史汇编将本装置明确归为圆形限制器/偏滤器配置；采用圆形等离子体理想边界：κ=b/a=1。是名义几何推算，不是逐炮平衡实测；原始装置论文尚待独立复核。 delta: AS_S03已读取历史汇编将本装置明确归为圆形限制器/偏滤器配置；采用圆形等离子体理想边界：δ=0。是名义几何推算，不是逐炮平衡实测；原始装置论文尚待独立复核。
A41: 日本 | B41: CSTN-II | C41: 0.4 | D41: 0.09 | E41: 1 | F41: 0 | G41: 0.003 | H41: 0.875 | I41: 文献汇总值，含理想圆形边界几何推算 | J41: 历史装置，现状未核实 | K41: 2012汇编 | L41: 常规 | M41: =6-COUNTBLANK(C41:H41) -> 6 | N41: S003 | O41: AS_cstn2 | P41: 历史汇编待原文复核 | R41: 名古屋大学 | S41: CSTN-I后继 | T41: 常规／球形托卡马克 | U41: 拉长比 κ；三角度 δ | V41: 3 | W41: kappa: AS_S03已读取历史汇编将本装置明确归为圆形限制器/偏滤器配置；采用圆形等离子体理想边界：κ=b/a=1。是名义几何推算，不是逐炮平衡实测；原始装置论文尚待独立复核。 delta: AS_S03已读取历史汇编将本装置明确归为圆形限制器/偏滤器配置；采用圆形等离子体理想边界：δ=0。是名义几何推算，不是逐炮平衡实测；原始装置论文尚待独立复核。
...

Sheet 参数证据明细
A1: 参数证据 · 每个值均可定位
A2: 每条装置记录展开为六个参数行（环向场 B_t 为 2026-09-14 第二轮新增）。保留限定符、证据层级、来源URL及定义注释；缺失值为空。
A5: 记录ID | B5: 国家／地区 | C5: 装置／版本 | D5: 参数 | E5: 采用值（含推算） | F5: 单位 | G5: 参数口径 | H5: 值的来源性质 | I5: 字段来源／位置 | J5: 来源URL | K5: 参数注释 | L5: 证据层级
A6: AS_best | B6: 中国 | C6: BEST | D6: 大半径 R | E6: 3.6 | F6: m | G6: 设计参数 | H6: 文献直接报告 | I6: S015 Table 2 | J6: https://www.preprints.org/manuscript/202606.0246 | K6: 所列κ95、δ95为Q≈5建模工况；源为2026预印本。 | L6: 仅检索摘要
A7: AS_best | B7: 中国 | C7: BEST | D7: 小半径 a | E7: 1.1 | F7: m | G7: 设计参数 | H7: 文献直接报告 | I7: S015 Table 2 | J7: https://www.preprints.org/manuscript/202606.0246 | K7: 所列κ95、δ95为Q≈5建模工况；源为2026预印本。 | L7: 仅检索摘要
A8: AS_best | B8: 中国 | C8: BEST | D8: 拉长比 κ | E8: 1.87 | F8: 无量纲 | G8: 设计参数 | H8: 文献直接报告 | I8: S015 Table 2 | J8: https://www.preprints.org/manuscript/202606.0246 | K8: 所列κ95、δ95为Q≈5建模工况；源为2026预印本。 | L8: 仅检索摘要
A9: AS_best | B9: 中国 | C9: BEST | D9: 三角度 δ | E9: 0.51 | F9: 无量纲 | G9: 设计参数 | H9: 文献直接报告 | I9: S015 Table 2 | J9: https://www.preprints.org/manuscript/202606.0246 | K9: 所列κ95、δ95为Q≈5建模工况；源为2026预印本。 | L9: 仅检索摘要
A10: AS_best | B10: 中国 | C10: BEST | D10: 总等离子体电流 Ip | E10: 7 | F10: MA | G10: 设计参数 | H10: 文献直接报告 | I10: S015 Table 2 | J10: https://www.preprints.org/manuscript/202606.0246 | K10: 所列κ95、δ95为Q≈5建模工况；源为2026预印本。 | L10: 仅检索摘要
A11: AS_best | B11: 中国 | C11: BEST | D11: 环向场 B_t | E11: 6.15 | F11: T | G11: 设计参数 | H11: 文献直接报告 | I11: 装置Bt汇总.csv (2026-09-14 轮A/B 复核) | K11: 口径: 设计值; 另一来源(indico.triumf.ca 405/4529)写 "toroidal field <6.1 T"〔IAEA FEC contribution 35557 — BEST (中国, R=3.6 m)〕
A12: AS_cfetr | B12: 中国 | C12: CFETR（2021混合运行情景） | D12: 大半径 R | E12: 7.2 | F12: m | G12: 设计参数（R7.2m、1GW hybrid scenario） | H12: 文献直接报告 | I12: S061 Appendix A Table 2，LLNL-JRNL-829024 | J12: https://www.osti.gov/servlets/purl/1883015 | K12: 整组采用2021 CFETR 1GW混合运行情景的Appendix A Table2，a=2.0与原2022汇总a2.2有实质版本差异，原值保存previous_parameters；不混拼。κ/δ该表未标95%磁面。 | L12: 全文核验
A13: AS_cfetr | B13: 中国 | C13: CFETR（2021混合运行情景） | D13: 小半径 a | E13: 2 | F13: m | G13: 设计参数（R7.2m、1GW hybrid scenario） | H13: 文献直接报告 | I13: S061 Appendix A Table 2，LLNL-JRNL-829024 | J13: https://www.osti.gov/servlets/purl/1883015 | K13: 整组采用2021 CFETR 1GW混合运行情景的Appendix A Table2，a=2.0与原2022汇总a2.2有实质版本差异，原值保存previous_parameters；不混拼。κ/δ该表未标95%磁面。 | L13: 全文核验
A14: AS_cfetr | B14: 中国 | C14: CFETR（2021混合运行情景） | D14: 拉长比 κ | E14: 2 | F14: 无量纲 | G14: 设计参数（R7.2m、1GW hybrid scenario） | H14: 文献直接报告 | I14: S061 Appendix A Table 2，LLNL-JRNL-829024 | J14: https://www.osti.gov/servlets/purl/1883015 | K14: 整组采用2021 CFETR 1GW混合运行情景的Appendix A Table2，a=2.0与原2022汇总a2.2有实质版本差异，原值保存previous_parameters；不混拼。κ/δ该表未标95%磁面。 | L14: 全文核验
A15: AS_cfetr | B15: 中国 | C15: CFETR（2021混合运行情景） | D15: 三角度 δ | E15: 0.52 | F15: 无量纲 | G15: 设计参数（R7.2m、1GW hybrid scenario） | H15: 文献直接报告 | I15: S061 Appendix A Table 2，LLNL-JRNL-829024 | J15: https://www.osti.gov/servlets/purl/1883015 | K15: 整组采用2021 CFETR 1GW混合运行情景的Appendix A Table2，a=2.0与原2022汇总a2.2有实质版本差异，原值保存previous_parameters；不混拼。κ/δ该表未标95%磁面。 | L15: 全文核验
A16: AS_cfetr | B16: 中国 | C16: CFETR（2021混合运行情景） | D16: 总等离子体电流 Ip | E16: 13.7 | F16: MA | G16: 设计参数（R7.2m、1GW hybrid scenario） | H16: 文献直接报告 | I16: S061 Appendix A Table 2，LLNL-JRNL-829024 | J16: https://www.osti.gov/servlets/purl/1883015 | K16: 整组采用2021 CFETR 1GW混合运行情景的Appendix A Table2，a=2.0与原2022汇总a2.2有实质版本差异，原值保存previous_parameters；不混拼。κ/δ该表未标95%磁面。 | L16: 全文核验
A17: AS_cfetr | B17: 中国 | C17: CFETR（2021混合运行情景） | D17: 环向场 B_t | E17: 5 | F17: T | G17: 设计参数（R7.2m、1GW hybrid scenario） | H17: 文献直接报告 | I17: 装置Bt汇总.csv (2026-09-14 轮A/B 复核) | K17: 设计值(等离子体中心)〔blanketfirst-wall-challenges-and-required-rampd-on-the-pathway〕
A18: AS_ct6 | B18: 中国 | C18: CT-6 | D18: 大半径 R | F18: m | G18: 无参数 | H18: 缺失 | K18: 名录/历史沿革证据已找到；尚未取得原始版本参数。 | L18: 仅名录
A19: AS_ct6 | B19: 中国 | C19: CT-6 | D19: 小半径 a | F19: m | G19: 无参数 | H19: 缺失 | K19: 名录/历史沿革证据已找到；尚未取得原始版本参数。 | L19: 仅名录
A20: AS_ct6 | B20: 中国 | C20: CT-6 | D20: 拉长比 κ | F20: 无量纲 | G20: 无参数 | H20: 缺失 | K20: 名录/历史沿革证据已找到；尚未取得原始版本参数。 | L20: 仅名录
A21: AS_ct6 | B21: 中国 | C21: CT-6 | D21: 三角度 δ | F21: 无量纲 | G21: 无参数 | H21: 缺失 | K21: 名录/历史沿革证据已找到；尚未取得原始版本参数。 | L21: 仅名录
A22: AS_ct6 | B22: 中国 | C22: CT-6 | D22: 总等离子体电流 Ip | F22: MA | G22: 无参数 | H22: 缺失 | K22: 名录/历史沿革证据已找到；尚未取得原始版本参数。 | L22: 仅名录
A23: AS_ct6 | B23: 中国 | C23: CT-6 | D23: 环向场 B_t | E23: 2 | F23: T | G23: 无参数 | H23: 文献直接报告 | I23: 装置Bt汇总.csv (2026-09-14 轮A/B 复核) | K23: 原文 "2TL" 为网页 OCR/排版讹误，应为 2 T。此为 CT-6 原型（中科院物理所，R=0.45 m, a=0.092 m），勿与 CT-6B (0.75 T) 混用。〔物理学报 (Acta Physica Sinica) 29, 577 (1980) — CT-6 装置报告〕
A24: AS_ct6b | B24: 中国 | C24: CT-6B | D24: 大半径 R | E24: 0.45 | F24: m | G24: 文献汇总值，含理想圆形边界几何推算 | H24: 文献直接报告 | I24: S002 Table 1 pp.S247–S248 | J24: https://golem.fjfi.cvut.cz/wiki/Library/others/GryaznevichM_Joint_Research_05.pdf | K24: 参数为2005综述历史快照；未声明各最优指标同时实现。 综述中斜体为暂定信息，尚未逐字段核对字体标记。 第二轮形状值依据历史汇编明确的圆形限制器配置推算；不能将κ/δ视作本行电流下的实测平衡，多源额定/汇总值不保证同时实现。 | L24: 全文核验
A25: AS_ct6b | B25: 中国 | C25: CT-6B | D25: 小半径 a | E25: 0.125 | F25: m | G25: 文献汇总值，含理想圆形边界几何推算 | H25: 文献直接报告 | I25: S002 Table 1 pp.S247–S248 | J25: https://golem.fjfi.cvut.cz/wiki/Library/others/GryaznevichM_Joint_Research_05.pdf | K25: 参数为2005综述历史快照；未声明各最优指标同时实现。 综述中斜体为暂定信息，尚未逐字段核对字体标记。 第二轮形状值依据历史汇编明确的圆形限制器配置推算；不能将κ/δ视作本行电流下的实测平衡，多源额定/汇总值不保证同时实现。 | L25: 全文核验
A26: AS_ct6b | B26: 中国 | C26: CT-6B | D26: 拉长比 κ | E26: 1 | F26: 无量纲 | G26: 文献汇总值，含理想圆形边界几何推算 | H26: 文献直接报告 | I26: S002 Table 1 pp.S247–S248 | J26: https://golem.fjfi.cvut.cz/wiki/Library/others/GryaznevichM_Joint_Research_05.pdf | K26: 参数为2005综述历史快照；未声明各最优指标同时实现。 综述中斜体为暂定信息，尚未逐字段核对字体标记。 第二轮形状值依据历史汇编明确的圆形限制器配置推算；不能将κ/δ视作本行电流下的实测平衡，多源额定/汇总值不保证同时实现。 | L26: 全文核验
A27: AS_ct6b | B27: 中国 | C27: CT-6B | D27: 三角度 δ | E27: 0 | F27: 无量纲 | G27: 文献汇总值，含理想圆形边界几何推算 | H27: 几何推算 | I27: S003 CT-6B条目：Circular Limiter/Divertor，理想边界几何推算 | J27: https://golem.fjfi.cvut.cz/wiki/History/table-of-tokamaks.pdf | K27: 【几何推算】AS_S03已读取历史汇编将本装置明确归为圆形限制器/偏滤器配置；采用圆形等离子体理想边界：δ=0。是名义几何推算，不是逐炮平衡实测；原始装置论文尚待独立复核。 参数为2005综述历史快照；未声明各最优指标同时实现。 综述中斜体为暂定信息，尚未逐字段核对字体标记。 第二轮形状值依据历史汇编明确的圆形限制器配置推算；不能将κ/δ视作本行电流下的实测平衡，多源额定/汇总值不保证同时实现。 | L27: 全文核验
A28: AS_ct6b | B28: 中国 | C28: CT-6B | D28: 总等离子体电流 Ip | E28: 0.03 | F28: MA | G28: 文献汇总值，含理想圆形边界几何推算 | H28: 文献直接报告 | I28: S002 Table 1 pp.S247–S248 | J28: https://golem.fjfi.cvut.cz/wiki/Library/others/GryaznevichM_Joint_Research_05.pdf | K28: 参数为2005综述历史快照；未声明各最优指标同时实现。 综述中斜体为暂定信息，尚未逐字段核对字体标记。 第二轮形状值依据历史汇编明确的圆形限制器配置推算；不能将κ/δ视作本行电流下的实测平衡，多源额定/汇总值不保证同时实现。 | L28: 全文核验
A29: AS_ct6b | B29: 中国 | C29: CT-6B | D29: 环向场 B_t | E29: 0.75 | F29: T | G29: 文献汇总值，含理想圆形边界几何推算 | H29: 文献直接报告 | I29: 装置Bt汇总.csv (2026-09-14 轮A/B 复核) | K29: 表格 TF〔S002 Gryaznevich 2005 ST综述 表格; S003 Balshaw 2012 表格〕
A30: AS_east | B30: 中国 | C30: EAST | D30: 大半径 R | E30: 1.8 | F30: m | G30: 装置额定参数 | H30: 文献直接报告 | I30: S004 The EAST tokamak | J30: https://www.nature.com/articles/srep32440 | K30: 2016装置能力参数，形状范围不能保证与1 MA同时实现。IAEA2022及早期设计给R=1.7,a=0.4；保留版本差异。 | L30: 仅检索摘要
A31: AS_east | B31: 中国 | C31: EAST | D31: 小半径 a | E31: 0.45 | F31: m | G31: 装置额定参数 | H31: 文献直接报告 | I31: S004 The EAST tokamak | J31: https://www.nature.com/articles/srep32440 | K31: 2016装置能力参数，形状范围不能保证与1 MA同时实现。IAEA2022及早期设计给R=1.7,a=0.4；保留版本差异。 | L31: 仅检索摘要
A32: AS_east | B32: 中国 | C32: EAST | D32: 拉长比 κ | E32: 1.5–2.0 | F32: 无量纲 | G32: 装置额定参数 | H32: 文献直接报告 | I32: S004 The EAST tokamak | J32: https://www.nature.com/articles/srep32440 | K32: 2016装置能力参数，形状范围不能保证与1 MA同时实现。IAEA2022及早期设计给R=1.7,a=0.4；保留版本差异。 | L32: 仅检索摘要
A33: AS_east | B33: 中国 | C33: EAST | D33: 三角度 δ | E33: 0.3–0.6 | F33: 无量纲 | G33: 装置额定参数 | H33: 文献直接报告 | I33: S004 The EAST tokamak | J33: https://www.nature.com/articles/srep32440 | K33: 2016装置能力参数，形状范围不能保证与1 MA同时实现。IAEA2022及早期设计给R=1.7,a=0.4；保留版本差异。 | L33: 仅检索摘要
A34: AS_east | B34: 中国 | C34: EAST | D34: 总等离子体电流 Ip | E34: 1 | F34: MA | G34: 装置额定参数 | H34: 文献直接报告 | I34: S004 The EAST tokamak | J34: https://www.nature.com/articles/srep32440 | K34: 2016装置能力参数，形状范围不能保证与1 MA同时实现。IAEA2022及早期设计给R=1.7,a=0.4；保留版本差异。 | L34: 仅检索摘要
A35: AS_east | B35: 中国 | C35: EAST | D35: 环向场 B_t | E35: 3.5 | F35: T | G35: 装置额定参数 | H35: 文献直接报告 | I35: 装置Bt汇总.csv (2026-09-14 轮A/B 复核) | K35: 设计/标称 Bo | CSV 并录值: 2.0 / 2.2 / 2.5 / 3.5 / ≤3.5〔S001 IAEA World Survey 2022 表格; Wesson2011_Tokamak_edition4〕
A36: AS_ehl2 | B36: 中国 | C36: EHL-2（2025平衡V43） | D36: 大半径 R | E36: 1.09 | F36: m | G36: 设计参数（V43平衡工况） | H36: 文献直接报告 | I36: S066 p.7 Table2 V43 | J36: https://pubs-en.cstam.org.cn/data/article/pst/preview/pdf/PST-2024-0305.pdf | K36: 五项均同原文Table2 V43直接数字：R是等离子体LCFS几何大半径RLCFS=1.09m，不是磁轴Rmag=1.24m；κδ为该边界形状。上一版官方总体R1.05m、Ip3MA保存在previous_parameters；本轮中途按A1.85换算的小半径已被原表直接数字取代。 | L36: 全文核验
A37: AS_ehl2 | B37: 中国 | C37: EHL-2（2025平衡V43） | D37: 小半径 a | E37: 0.6 | F37: m | G37: 设计参数（V43平衡工况） | H37: 文献直接报告 | I37: S066 p.7 Table2 V43 | J37: https://pubs-en.cstam.org.cn/data/article/pst/preview/pdf/PST-2024-0305.pdf | K37: 五项均同原文Table2 V43直接数字：R是等离子体LCFS几何大半径RLCFS=1.09m，不是磁轴Rmag=1.24m；κδ为该边界形状。上一版官方总体R1.05m、Ip3MA保存在previous_parameters；本轮中途按A1.85换算的小半径已被原表直接数字取代。 | L37: 全文核验
A38: AS_ehl2 | B38: 中国 | C38: EHL-2（2025平衡V43） | D38: 拉长比 κ | E38: 2.26 | F38: 无量纲 | G38: 设计参数（V43平衡工况） | H38: 文献直接报告 | I38: S066 p.7 Table2 V43 | J38: https://pubs-en.cstam.org.cn/data/article/pst/preview/pdf/PST-2024-0305.pdf | K38: 五项均同原文Table2 V43直接数字：R是等离子体LCFS几何大半径RLCFS=1.09m，不是磁轴Rmag=1.24m；κδ为该边界形状。上一版官方总体R1.05m、Ip3MA保存在previous_parameters；本轮中途按A1.85换算的小半径已被原表直接数字取代。 | L38: 全文核验
A39: AS_ehl2 | B39: 中国 | C39: EHL-2（2025平衡V43） | D39: 三角度 δ | E39: 0.4 | F39: 无量纲 | G39: 设计参数（V43平衡工况） | H39: 文献直接报告 | I39: S066 p.7 Table2 V43 | J39: https://pubs-en.cstam.org.cn/data/article/pst/preview/pdf/PST-2024-0305.pdf | K39: 五项均同原文Table2 V43直接数字：R是等离子体LCFS几何大半径RLCFS=1.09m，不是磁轴Rmag=1.24m；κδ为该边界形状。上一版官方总体R1.05m、Ip3MA保存在previous_parameters；本轮中途按A1.85换算的小半径已被原表直接数字取代。 | L39: 全文核验
A40: AS_ehl2 | B40: 中国 | C40: EHL-2（2025平衡V43） | D40: 总等离子体电流 Ip | E40: 3 | F40: MA | G40: 设计参数（V43平衡工况） | H40: 文献直接报告 | I40: S066 p.7 Table2 V43 | J40: https://pubs-en.cstam.org.cn/data/article/pst/preview/pdf/PST-2024-0305.pdf | K40: 五项均同原文Table2 V43直接数字：R是等离子体LCFS几何大半径RLCFS=1.09m，不是磁轴Rmag=1.24m；κδ为该边界形状。上一版官方总体R1.05m、Ip3MA保存在previous_parameters；本轮中途按A1.85换算的小半径已被原表直接数字取代。 | L40: 全文核验
A41: AS_ehl2 | B41: 中国 | C41: EHL-2（2025平衡V43） | D41: 环向场 B_t | E41: 3 | F41: T | G41: 设计参数（V43平衡工况） | H41: 文献直接报告 | I41: 装置Bt汇总.csv (2026-09-14 轮A/B 复核) | K41: 文中语句〔S066〕
A42: AS_exl50 | B42: 中国 | C42: EXL-50 | D42: 大半径 R | E42: 0.6 | F42: m | G42: 设计参数 | H42: 文献直接报告 | I42: S038 p.1 Design Parameter Goals | J42: https://www.aappsdpp.org/DPP2021/MF-1/5539.pdf | K42: 2021 AAPPS设计目标同表；2020设计报告R=.58,a=.41为另一版本，未混用。目标电流0.5 MA不代表实验已实现。 | L42: 全文核验
...

Sheet 来源文献
A1: 来源文献 · 引用索引
A2: 241 条按DOI或URL去重的来源；原始索引保留在末列。全文、官方页面、摘要及检索摘要分别标记。
A5: 来源编号 | B5: 文献／资料标题 | C5: 作者／机构 | D5: 年份 | E5: 类型 | F5: 访问证据 | G5: 来源URL | H5: DOI | I5: 页码／表号／章节 | J5: 原始索引
A6: S001 | B6: World Survey of Fusion Devices 2022 | C6: IAEA | D6: 2022 | E6: 官方目录 | F6: 全文 | G6: https://www-pub.iaea.org/MTCD/Publications/PDF/CRCP-FUS-001webRev.pdf | I6: 各装置章及参数表；各装置章节及参数表；pp.19–22,76–81,152–153；各装置章节/参数表 | J6: AS_S01; EU_S01; AM_S01; RW_S01
A7: S002 | B7: Joint research using small tokamaks | C7: M. P. Gryaznevich et al. | D7: 2005 | E7: 综述 | F7: 全文 | G7: https://golem.fjfi.cvut.cz/wiki/Library/others/GryaznevichM_Joint_Research_05.pdf | H7: 10.1088/0029-5515/45/10/S20 | I7: Table 1 pp. S247–S248；p. S246口径说明；Table 1 continued p.S248；§2 p.S246；Table 1, pp. S247–S248；斜杠定义见S246 | J7: AS_S02; AM_S42; RW_S02
A8: S003 | B8: Comparison table of 'Conventional' Tokamaks | C8: N. H. Balshaw | D8: 2012 | E8: 历史资料 | F8: 全文 | G8: https://golem.fjfi.cvut.cz/wiki/History/table-of-tokamaks.pdf | I8: 各装置行，末页口径；12页；2012年4月版；12页历史名录；各装置条目；2012-04版 | J8: AS_S03; EU_S02; AM_S20; RW_S10
A9: S004 | B9: 3D passive stabilization of n=0 MHD modes in EAST tokamak | D9: 2016 | E9: 原始论文 | F9: 检索摘要 | G9: https://www.nature.com/articles/srep32440 | H9: 10.1038/srep32440 | I9: The EAST tokamak section | J9: AS_S04
A10: S005 | B10: EXL Fusion Power Technology R&D | C10: Y.-K. M. Peng | D10: 2020 | E10: 设计报告 | F10: 检索摘要 | G10: https://firefusionpower.org/FPA20_Peng_EXL_fusion_ENN.pdf | I10: slide 6 | J10: AS_S05
A11: S006 | B11: The KSTAR Tokamak | C11: D. I. Choi et al. | D11: 1998 | E11: 原始论文 | F11: 全文 | G11: https://w3.pppl.gov/theory-main/PublicTheoryPage/bin/PAPERS/paper1997c.pdf | I11: Table I p.216 | J11: AS_S06
A12: S007 | B12: Living with Plasmas | C12: IPR | D12: 2017 | E12: 官方页面 | F12: 检索摘要 | G12: https://www.ipr.res.in/outreach/documents/Living%20with%20plasmas-English-Final_Oct%202017.pdf | I12: SST-1 device description | J12: AS_S07
A13: S008 | B13: Recent progress of JT-60SA project for the promotion of fusion research and development | C13: H. Shirai, P. Barabaschi, Y. Kamada and JT-60SA team | D13: 2015 | E13: 原始论文 | F13: 全文 | G13: https://www.jstage.jst.go.jp/article/jsmeicone/2015.23/0/2015.23__ICONE23-1_296/_pdf | I13: Table 1 | J13: AS_S08
A14: S009 | B14: JT-60SA増力作業 | C14: QST | D14: 2026 | E14: 官方页面 | F14: 检索摘要 | G14: https://www.qst.go.jp/site/jt60/progress.html | I14: 2026-08-06更新 | J14: AS_S09
A15: S010 | B15: Changes in the JT-60SA project organization | C15: JT-60SA | D15: 2026 | E15: 官方页面 | F15: 检索摘要 | G15: https://www.jt60sa.org/wp/changes-in-the-jt-60sa-project-organization/ | I15: 2026-05-14 | J15: AS_S10
A16: S011 | B16: The Preliminary design of SUNIST-2:A Spherical Tokamak | D16: 2025 | E16: 原始论文 | F16: 检索摘要 | G16: https://www.sciencedirect.com/science/article/pii/S0920379625000675 | H16: 10.1016/j.fusengdes.2025.114865 | I16: Abstract; Introduction | J16: AS_S11
A17: S012 | B17: Startorus Successfully Operates the First Experimental Fusion Device | C17: Startorus Fusion | D17: 2023 | E17: 官方页面 | F17: 检索摘要 | G17: https://startorus.com/progress-news/154.html | I17: first-round operation | J17: AS_S12
A18: S013 | B18: Overview of EXL-50 research progress | D18: 2025 | E18: 原始论文 | F18: 检索摘要 | G18: https://doi.org/10.1088/1741-4326/adf239 | H18: 10.1088/1741-4326/adf239 | I18: Table 3; EXL-50U section | J18: AS_S13
A19: S014 | B19: Development and construction of magnet system for world’s first full high temperature superconducting tokamak | C19: Z. Y. Li et al. | D19: 2024 | E19: 原始论文 | F19: 检索摘要 | G19: https://www.sciencedirect.com/science/article/pii/S2772830724000541 | H19: 10.1016/j.supcon.2024.100137 | I19: Abstract | J19: AS_S14
A20: S015 | B20: Simulation and Comparative Analysis of Advanced Scenarios for High- and Low-Temperature Superconducting Tokamak Using METIS Code | D20: 2026 | E20: 原始论文 | F20: 检索摘要 | G20: https://www.preprints.org/manuscript/202606.0246 | I20: Table 2 BEST Q≈5 column | J20: AS_S15
A21: S016 | B21: BEST装置建设阶段性进展 | C21: ASIPP | D21: 2026 | E21: 官方页面 | F21: 检索摘要 | G21: https://www.ipp.cas.cn/xwdt/tpxw/202605/t20260501_835977.html | I21: 2026-05-01 | J21: AS_S16
A22: S017 | B22: NTST, a negative triangularity spherical tokamak | C22: Yi Tan; Shouzhi Wang et al. | D22: 2025 | E22: 原始论文 | F22: 全文 | G22: https://conferences.iaea.org/event/392/papers/35885/files/13814-3334%2C%20NTST%5EJ%20A%20NEGATIVE%20TRIANGULARITY%20SPHERICAL%20TOKAMAK%20Manuscript.pdf | I22: §2 pp.1–2 | J22: AS_S17
A23: S018 | B23: The first plasma breakdown in Thailand Tokamak-1 using the Ohmic heating and double swing flux methods based on magnetic field analysis | D23: 2025 | E23: 原始论文 | F23: 检索摘要 | G23: https://www.sciencedirect.com/science/article/pii/S0920379624006318 | H23: 10.1016/j.fusengdes.2024.114781 | I23: Abstract; Introduction | J23: AS_S18
A24: S019 | B24: Conceptual Design of Formosa Integrated Research Spherical Tokamak | C24: WenYi Chen et al. | D24: 2025 | E24: 原始论文 | F24: 摘要 | G24: https://meetings-archive.aps.org/dpp/2025/bp13/123/ | I24: APS DPP 2025 abstract | J24: AS_S19
A25: S020 | B25: FAST Project | C25: Starlight Engine | D25: 2026 | E25: 官方页面 | F25: 页面 | G25: https://sle.energy/en/fast-project/ | I25: Specification of FAST table | J25: AS_S20
A26: S021 | B26: Design and Analysis of SST-2 Vacuum Vessel | D26: 2016 | E26: 原始论文 | F26: 检索摘要 | G26: https://nucleus.iaea.org/sites/fusionportal/Shared%20Documents/FEC%202016/fec2016-preprints/preprint0496.pdf | I26: Table 1 | J26: AS_S21
A27: S022 | B27: K-DEMO and CPD | C27: KFE | D27: 2025 | E27: 设计报告 | F27: 检索摘要 | G27: https://conferences.iaea.org/event/392/contributions/35845/attachments/19823/36305/%282025-10-18%2C%20FEC%29%20K-DEMO%20and%20CPD%20v2.pdf | I27: Key parameters for a preliminary K-DEMO system design | J27: AS_S22
A28: S023 | B28: Observation of High Recycling Steady H-mode Edge and Compatibility with Improved Core Confinement Mode on JFT-2M | C28: K. Kamiya et al. | D28: 2002 | E28: 原始论文 | F28: 全文 | G28: https://www-pub.iaea.org/MTCD/Publications/PDF/csp_019c/pdf/exp2_05.pdf | I28: p.1 §1–2 | J28: AS_S23
A29: S024 | B29: JFT-2Mの紹介 | C29: QST | D29: 2025 | E29: 官方页面 | F29: 页面 | G29: https://www.qst.go.jp/site/jt60/5125.html | I29: 装置の大きさ table; page title | J29: AS_S24
A30: S025 | B30: 三大トカマク装置の特徴と研究成果 | C30: JAEA ATOMICA | D30: 2004 | E30: 官方页面 | F30: 页面 | G30: https://atomica.jaea.go.jp/data/detail/dat_detail_07-05-01-07.html | I30: §1(1) | J30: AS_S25
A31: S026 | B31: LHD glossary: JIPP T-IIU | C31: NIFS | E31: 官方页面 | F31: 检索摘要 | G31: https://www-lhd.nifs.ac.jp/pub/glossary_jp.html | I31: JIPP T-IIU | J31: AS_S26
A32: S027 | B32: Frontier Issues and Progress of Controlled Nuclear Fusion Science and Technology | D32: 2018 | E32: 综述 | F32: 检索摘要 | G32: https://www.engineering.org.cn/sscae/EN/1160078617508110927 | I32: 中国装置历史段 | J32: AS_S27
A33: S028 | B33: Parameter Comparison of TST-M and TST-2 | C33: University of Tokyo | D33: 1999 | E33: 官方页面 | F33: 页面 | G33: https://fusion.k.u-tokyo.ac.jp/research/tst-2/TST-2.html | I33: Plasma Parameters comparison | J33: AS_S28
A34: S029 | B34: Plasma Shape Reconstruction of Spherical Tokamak using CCS Method | C34: F. Wang et al. | D34: 2007 | E34: 原始论文 | F34: 全文 | G34: https://www.jspf.or.jp/PFR/PDF/pfr2007_02-S1095.pdf | H34: 10.1585/pfr.2.S1095 | I34: p.S1095-2 §3 | J34: AS_S29
A35: S030 | B35: Conceptual Design Activities of FDS Series Fusion Power Plants | C35: Yican Wu and FDS Team | D35: 2005 | E35: 设计报告 | F35: 全文 | G35: https://www-pub.iaea.org/mtcd/publications/pdf/p1250-cd/presentations/ppca1-iii_pres.pdf | I35: slide 20 (PDF p.20); slides 3,17 | J35: AS_S30
A36: S031 | B36: Design Issues on Compact Low Aspect Ratio DEMO Reactor, SlimCS | C36: K. Tobita et al. | D36: 2008 | E36: 原始论文 | F36: 全文 | G36: https://www-pub.iaea.org/MTCD/Meetings/FEC2008/ft_p3-9.pdf | I36: p.1 Table 1 | J36: AS_S31
A37: S032 | B37: Design and mechanical analysis of the PRAGYA tokamak vacuum vessel | C37: Ravi Gupta et al. | D37: 2026 | E37: 原始论文 | F37: 摘要 | G37: https://arxiv.org/abs/2603.11549 | H37: 10.48550/arXiv.2603.11549 | I37: Abstract, arXiv:2603.11549 | J37: AS_S32
A38: S033 | B38: EHL-2 | C38: ENN Energy Research Institute | E38: 官方页面 | F38: 页面 | G38: https://en.ennresearch.com/researchfield/Compactfusion/EHL_2/ | I38: EHL-2 parameters | J38: AS_S33
A39: S034 | B39: Devices | C39: Energy Singularity | E39: 官方页面 | F39: 页面 | G39: https://energysingularity.cn/en/devices.html | I39: HH170 section | J39: AS_S34
A40: S035 | B40: The Ideal MHD Stability in the Large Aspect Ratio KT-2 Tokamak | D40: 1996 | E40: 设计报告 | F40: 全文 | G40: https://www.osti.gov/etdeweb/servlets/purl/430108 | I40: KAERI/TR-608/96, Table 1.1,1.2 | J40: AS_S35
A41: S036 | B41: [KFE presentation on Blanket Test Infrastructure and Compact Pilot Device] | C41: Mu Young Ahn, KFE | D41: 2025 | E41: 设计报告 | F41: 全文 | G41: https://conferences.iaea.org/event/406/contributions/37079/attachments/20817/35235/Mu%20Young%20Ahn%20KFE.pdf | I41: table Parameters: CPD draft (Tokamak)/(Spherical) | J41: AS_S36
A42: S037 | B42: Evolution of the ITER program and prospect for the next-step fusion DEMO reactors: status of the fusion energy R&D as ultimate source of energy | C42: S. Matsuda and K. Tobita | D42: 2013 | E42: 综述 | F42: 检索摘要 | G42: https://www.tandfonline.com/doi/pdf/10.1080/00223131.2013.773166 | H42: 10.1080/00223131.2013.773166 | I42: p.336 Table 3 | J42: AS_S37
...

Sheet 缺失与待核实
A1: 缺失与待核实 · 保留调查边界
A2: 包含已收录装置的缺失字段，以及候选、版本冲突和排除依据；此表不是额外已确认装置的计数。
A5: 国家／地区 | B5: 装置／候选 | C5: 问题类型 | D5: 缺失／冲突说明 | E5: 下一步来源／已用来源 | F5: 关联记录ID | G5: 本轮已查词组／文献 | H5: 本轮未补原因
A6: 日本/中国 | B6: 历史汇编19行 | C6: 候选／冲突／覆盖缺口 | D6: CSTN-I/II/III/AC、FY-1、HL-1、HT-6B、JFT-2/2a、JIPP T-II、TNT/TNT-A、TODOROKI-I、TORIUT-3/4/5、TRIAM、WT-1/2：已读Balshaw，尚未逐台回溯原始论文。 | E6: 各实验室历史年报与原装置建造论文
A7: 日本 | B7: NUCTE-ST | C7: 候选／冲突／覆盖缺口 | D7: 2005综述κ=10、R=.062m、Ip=.34MA为极端值，原始压缩/紧凑环形成工况与尺寸定义待核；保留来源值并标注异常。 | E7: Nihon University NUCTE-ST原始脉冲形成论文
A8: 日本 | B8: PLATO | C8: 候选／冲突／覆盖缺口 | D8: IAEA2022计划R=.7,a=.25；Kyushu实验室当前资源页另列R=.6,a=.2及2020首次放电，版本与名录年份冲突。 | E8: https://www.riam.kyushu-u.ac.jp/plasma/menu/en/equipment-e.html
A9: 日本 | B9: TOKASTAR-2 | C9: 候选／冲突／覆盖缺口 | D9: 第二轮已读取2010原始论文并核验Table2，录入R=.11m,a=.045m,Ip=.0025MA设计平衡；κδ未报。2010实际约25A与设计2.5kA分开说明。 | E9: AS_S57 Table2；后续2016实测平衡论文
A10: 日本 | B10: TOKASTAR / C-TOKASTAR | C10: 候选／冲突／覆盖缺口 | D10: 第二轮已读2009原始论文：TOKASTAR理论N=2投影椭圆度约2.0、C-TOKASTAR实验等离子体R约.02m已补；其余缺项与三维混合配置定义仍待核。 | E10: AS_S56及后续磁面重建论文
A11: 日本/巴西 | B11: NOVA-I / NOVA-II / NOVA-FURG | C11: 候选／冲突／覆盖缺口 | D11: NOVA-II迁移关系已录；NOVA-I与II的原始日本几何/电流及版本边界未核。 | E11: 京都大学历史记录及NOVA-II原始论文
A12: 中国/日本 | B12: CT-6 / KT-5 / HYBTOK-I / HT-1 / TST（原始） | C12: 候选／冲突／覆盖缺口 | D12: KT-5已由1987论文的JPRS原始英文摘要补R=.30m,a=.045m,Ip>.005MA；CT-6已找到1980原始论文DOI 10.7498/aps.29.577与R=.45m,a=.092m,Ip=.03MA摘要线索，但出版社访问403且可读检索镜像域名异常，暂不采值。HYBTOK-I等仍属候选。 | E12: CT-6原始出版社全文；KT-5见AS_S62
A13: 日本 | B13: VECTOR / DEMO-2001 / A-SSTR / Demo-CREST / NTT | C13: 候选／冲突／覆盖缺口 | D13: 公开日本概念设计候选，未完成五参数与版本核查；SSTR/A-SSTR2/CREST/SlimCS/GNOME/JA-DEMO已覆盖。 | E13: JAERI/JAEA、CRIEPI原始设计报告
A14: 日本 | B14: JT-60SU / JT-60SC | C14: 候选／冲突／覆盖缺口 | D14: JT-60系列被研究的历史升级方案；尚未明确已完成设计范围、参数与JT-60SA继承边界。 | E14: JT-60升级历史设计报告
A15: 中国 | B15: HH380 / CTRFR-1 / EHL-3B | C15: 候选／冲突／覆盖缺口 | D15: 私营商业后续装置候选，可能仅路线图代号，未取得足够定型设计参数证据。 | E15: 企业技术白皮书和期刊设计论文
A16: 印度 | B16: RAGYA / PRANIQ | C16: 候选／冲突／覆盖缺口 | D16: Pranos路线图中命名，设计成熟程度、参数及场址尚未全文核对。 | E16: https://nucleus.iaea.org/sites/connect/FUSEpublic/SitePages/PRANOS.aspx
A17: 印度 | B17: 印度DEMO / FNS / SST Bharat | C17: 候选／冲突／覆盖缺口 | D17: SST-2之外概念名与国家路线图关系未完整核验，避免重名重复。 | E17: IPR / DAE正式设计报告
... A52: 俄罗斯 | B52: TMP（早期陶瓷环） | C52: 候选／冲突／覆盖缺口 | D52: 边界历史装置，需确认与TMB别名以及tokamak定义 | E52: Balshaw2012 p.10；Smirnov2010
A53: 中国 | B53: CT-6 | C53: 已收录参数缺失 | D53: 缺失字段：大半径 R；小半径 a；拉长比 κ；三角度 δ；总等离子体电流 Ip。['R_m：已进行第二轮针对性检索；所读来源未给同版本可靠值，或原始全文尚未获取/定义未消歧，见round2_search_asia.json逐装置记录', 'a_m：已进行第二轮针对性检索；所读来源未给同版本可靠值，或原始全文尚未获取/定义未消歧，见round2_search_asia.json逐装置记录', 'kappa：已进行第二轮针对性检索；所读来源未给同版本可靠值，或原始全文尚未获取/定义未消歧，见round2_search_asia.json逐装置记录', 'delta：已进行第二轮针对性检索；所读来源未给同版本可靠值，或原始全文尚未获取/定义未消歧，见round2_search_asia.json逐装置记录', 'Ip_MA：已进行第二轮针对性检索；所读来源未给同版本可靠值，或原始全文尚未获取/定义未消歧，见round2_search_asia.json逐装置记录'] | E53: S027 | F53: AS_ct6 | G53: "CT-6" tokamak parameters major radius plasma current；CT-6 托卡马克 研究 1980 577 587 | H53: 找到原论文CT-6 TOKAMAK RESEARCH I，Acta Phys Sin 1980 29(5)577–587，DOI10.7498/aps.29.577，摘要线索R.45,a.092,Ip.03。原出版社403/DOI失败；检索可读副本站点显示异常赌博站名，未独立核验，故暂不采值。κδ也未报告。
A54: 中国 | B54: EXL-50U | C54: 已收录参数缺失 | D54: 缺失字段：小半径 a；三角度 δ。['a_m：已进行第二轮针对性检索；所读来源未给同版本可靠值，或原始全文尚未获取/定义未消歧，见round2_search_asia.json逐装置记录', 'delta：已进行第二轮针对性检索；所读来源未给同版本可靠值，或原始全文尚未获取/定义未消歧，见round2_search_asia.json逐装置记录'] | E54: S013 | F54: AS_exl50u | G54: EXL-50U "minor radius" "triangularity"；"EXL-50U" "minor radius" "triangularity" | H54: 原文公开R与A范围，但未给端点配对，不能把Rmin/Amax和Rmax/Amin伪装成实际a范围。δ尚缺对应2025名录工况；2026H模论文为后续入口。
A55: 中国 | B55: FY-1 | C55: 已收录参数缺失 | D55: 缺失字段：三角度 δ。['delta：已进行第二轮针对性检索；所读来源未给同版本可靠值，或原始全文尚未获取/定义未消歧，见round2_search_asia.json逐装置记录'] | E55: S003 | F55: AS_fy1 | G55: 本地Balshaw2012 FY-1 a b plasma；"FY-1" "tokamak" elliptical triangularity | H55: Balshaw明确plasma a10cm,b25cm，已据此推κ2.5；Non-Circular本身不足以证明ellipse或δ0。原始δ未取得。
A56: 中国 | B56: HH170 | C56: 已收录参数缺失 | D56: 缺失字段：小半径 a；拉长比 κ；三角度 δ；总等离子体电流 Ip。['a_m：已进行第二轮针对性检索；所读来源未给同版本可靠值，或原始全文尚未获取/定义未消歧，见round2_search_asia.json逐装置记录', 'kappa：已进行第二轮针对性检索；所读来源未给同版本可靠值，或原始全文尚未获取/定义未消歧，见round2_search_asia.json逐装置记录', 'delta：已进行第二轮针对性检索；所读来源未给同版本可靠值，或原始全文尚未获取/定义未消歧，见round2_search_asia.json逐装置记录', 'Ip_MA：已进行第二轮针对性检索；所读来源未给同版本可靠值，或原始全文尚未获取/定义未消歧，见round2_search_asia.json逐装置记录'] | E56: S034 | F56: AS_hh170 | G56: "HH170" "plasma current" "minor" | H56: 官方仅公开R1.5及磁体/路线图目标。未获得a/κ/δ/Ip原始设计表；磁体10T不代替等离子体电流。
A57: 中国 | B57: HH70 | C57: 已收录参数缺失 | D57: 缺失字段：拉长比 κ；三角度 δ；总等离子体电流 Ip。['kappa：已进行第二轮针对性检索；所读来源未给同版本可靠值，或原始全文尚未获取/定义未消歧，见round2_search_asia.json逐装置记录', 'delta：已进行第二轮针对性检索；所读来源未给同版本可靠值，或原始全文尚未获取/定义未消歧，见round2_search_asia.json逐装置记录', 'Ip_MA：已进行第二轮针对性检索；所读来源未给同版本可靠值，或原始全文尚未获取/定义未消歧，见round2_search_asia.json逐装置记录'] | E57: S014 | F57: AS_hh70 | G57: HH70 tokamak "elongation" "triangularity"；"HH70" "plasma current" | H57: 已查企业进展与磁体论文，长脉冲时长有报道，但不能换算Ip；κ/δ尚未取得装置平衡表。
A58: 中国 | B58: J-TEXT | C58: 已收录参数缺失 | D58: 缺失字段：拉长比 κ；三角度 δ。['kappa：已进行第二轮针对性检索；所读来源未给同版本可靠值，或原始全文尚未获取/定义未消歧，见round2_search_asia.json逐装置记录', 'delta：已进行第二轮针对性检索；所读来源未给同版本可靠值，或原始全文尚未获取/定义未消歧，见round2_search_asia.json逐装置记录'] | E58: S001 | F58: AS_jtext | G58: "J-TEXT" circular plasma triangularity original | H58: 2021 J-TEXT偏滤器原文预印本URL在实际下载时返回HTML；检索显示κ约.83/δ约-.16，但不能配对2022名录R/a/Ip。另有近圆形原始论文线索，尚未取得足够可核验全文。不能由圆形真空室代替等离子体边界。
A59: 中国 | B59: KT-5 | C59: 已收录参数缺失 | D59: 缺失字段：拉长比 κ；三角度 δ。['kappa：已进行第二轮针对性检索；所读来源未给同版本可靠值，或原始全文尚未获取/定义未消歧，见round2_search_asia.json逐装置记录', 'delta：已进行第二轮针对性检索；所读来源未给同版本可靠值，或原始全文尚未获取/定义未消歧，见round2_search_asia.json逐装置记录'] | E59: S027; S062 | F59: AS_kt5 | G59: "KT-5" tokamak Hefei parameters；KT-5 托卡马克 初步 实验 1987 温逸智；原始全文参数核验：Preliminary Measurements of Tokamak KT-5（原1987论文英文摘要，JPRS-CST-88-003译载） | H59: JPRS原始英文摘要转录已补R/a/Ip，文中未报κ/δ；不从后续KT-5C圆形配置继承。
A60: 中国 | B60: SUNIST-1 | C60: 已收录参数缺失 | D60: 缺失字段：三角度 δ。['delta：已进行第二轮针对性检索；所读来源未给同版本可靠值，或原始全文尚未获取/定义未消歧，见round2_search_asia.json逐装置记录'] | E60: S002 | F60: AS_sunist | G60: SUNIST-2 "elongation" "triangularity"；"SUNIST-2" "elongation"；"SUNIST" "triangularity" | H60: 已检索SUNIST原装置形状论文，结果大量指向SUNIST-2和仅适用于SUNIST的理论扫描。未找到原SUNIST-1与2005参数组可配对的δ；不能从SUNIST-2挪用。
A61: 中国台湾 | B61: FIRST | C61: 已收录参数缺失 | D61: 缺失字段：总等离子体电流 Ip。['Ip_MA：已进行第二轮针对性检索；所读来源未给同版本可靠值，或原始全文尚未获取/定义未消歧，见round2_search_asia.json逐装置记录'] | E61: S019 | F61: AS_first | G61: "Formosa Integrated Research Spherical Tokamak" current | H61: 已读APS2025原始摘要R/a/κ/δ/B，无Ip；另查NARI官方计划及2026会议条目，未取得可靠总等离子体电流。
A62: 日本 | B62: A-SSTR2 | C62: 已收录参数缺失 | D62: 缺失字段：拉长比 κ；三角度 δ。['kappa：已进行第二轮针对性检索；所读来源未给同版本可靠值，或原始全文尚未获取/定义未消歧，见round2_search_asia.json逐装置记录', 'delta：已进行第二轮针对性检索；所读来源未给同版本可靠值，或原始全文尚未获取/定义未消歧，见round2_search_asia.json逐装置记录'] | E62: S037 | F62: AS_asstr2 | G62: "A-SSTR2" "triangularity"；"A-SSTR2" "elongation" | H62: 原始A-SSTR2论文/高拉长设计讨论入口已查，尚未取得可核验对应R6.2/a1.5/Ip12版本κδ表；不可用SSTR或ARIES-AT代替。
A63: 日本 | B63: C-TOKASTAR | C63: 已收录参数缺失 | D63: 缺失字段：小半径 a；拉长比 κ；三角度 δ；总等离子体电流 Ip。['a_m：已进行第二轮针对性检索；所读来源未给同版本可靠值，或原始全文尚未获取/定义未消歧，见round2_search_asia.json逐装置记录', 'kappa：已进行第二轮针对性检索；所读来源未给同版本可靠值，或原始全文尚未获取/定义未消歧，见round2_search_asia.json逐装置记录', 'delta：已进行第二轮针对性检索；所读来源未给同版本可靠值，或原始全文尚未获取/定义未消歧，见round2_search_asia.json逐装置记录', 'Ip_MA：已进行第二轮针对性检索；所读来源未给同版本可靠值，或原始全文尚未获取/定义未消歧，见round2_search_asia.json逐装置记录'] | E63: S001; S056 | F63: AS_ctokastar | G63: "TOKASTAR" "C-TOKASTAR" plasma parameters | H63: 2009原文只给等离子体R约2cm以及线圈尺寸，未给a/κ/δ/托卡马克环向总电流；辉光磁面验证属于混合装置，电子发射电流不能作Ip。
A64: 日本 | B64: CPD（Compact PWI experimental Device） | C64: 已收录参数缺失 | D64: 缺失字段：拉长比 κ；三角度 δ。['kappa：已进行第二轮针对性检索；所读来源未给同版本可靠值，或原始全文尚未获取/定义未消歧，见round2_search_asia.json逐装置记录', 'delta：已进行第二轮针对性检索；所读来源未给同版本可靠值，或原始全文尚未获取/定义未消歧，见round2_search_asia.json逐装置记录'] | E64: S029 | F64: AS_cpd_jp | G64: "CPD" Kyushu tokamak elongation triangularity | H64: 原始CCS磁面重建文章已读R/a/Ip；κδ未报告对应参数。Kyushu CPD与韩国CPD设计不可混用。
... A159: 澳大利亚 | B159: Flinders Tokamak | C159: 已收录参数缺失 | D159: 缺失字段：三角度 δ。delta：本轮所查资料未报告，或定义／版本冲突未解决 | E159: S002 | F159: RW_FLINDERS | G159: Flinders tokamak triangularity；Flinders tokamak cross-section elongation；Gryaznevich2005 Table1 | H159: 小ST与Flinders Rotamak不能混同；所查团队小机综述未给δ数字。

Sheet 本轮补缺与修订
A1: 本轮补缺与修订 · 保留前后值
A2: 补缺、新增记录与版本调整分别计数。参考工况改变时整组替换；几何推算有独立说明。
A5: 国家／地区 | B5: 装置／版本 | C5: 参数 | D5: 上一版值 | E5: 本轮值 | F5: 变更类别 | G5: 几何推算说明 | H5: 本轮字段来源 | I5: 记录ID
A6: 中国 | B6: CFETR（2021混合运行情景） | C6: 小半径 a | D6: 2.2 | E6: 2 | F6: 重核／版本调整 | H6: S061 Appendix A Table 2，LLNL-JRNL-829024 | I6: AS_cfetr
A7: 中国 | B7: CFETR（2021混合运行情景） | C7: 三角度 δ | E7: 0.52 | F7: 补缺 | H7: S061 Appendix A Table 2，LLNL-JRNL-829024 | I7: AS_cfetr
A8: 中国 | B8: CFETR（2021混合运行情景） | C8: 总等离子体电流 Ip | D8: 14 | E8: 13.7 | F8: 重核／版本调整 | H8: S061 Appendix A Table 2，LLNL-JRNL-829024 | I8: AS_cfetr
A9: 中国 | B9: CT-6B | C9: 三角度 δ | E9: 0 | F9: 补缺 | G9: AS_S03已读取历史汇编将本装置明确归为圆形限制器/偏滤器配置；采用圆形等离子体理想边界：δ=0。是名义几何推算，不是逐炮平衡实测；原始装置论文尚待独立复核。 | H9: S003 CT-6B条目：Circular Limiter/Divertor，理想边界几何推算 | I9: AS_ct6b
A10: 中国 | B10: EHL-2（2025平衡V43） | C10: 大半径 R | D10: 1.05 | E10: 1.09 | F10: 重核／版本调整 | H10: S066 p.7 Table2 V43 | I10: AS_ehl2
A11: 中国 | B11: EHL-2（2025平衡V43） | C11: 小半径 a | E11: 0.6 | F11: 补缺 | H11: S066 p.7 Table2 V43 | I11: AS_ehl2
A12: 中国 | B12: EHL-2（2025平衡V43） | C12: 拉长比 κ | E12: 2.26 | F12: 补缺 | H12: S066 p.7 Table2 V43 | I12: AS_ehl2
A13: 中国 | B13: EHL-2（2025平衡V43） | C13: 三角度 δ | E13: 0.4 | F13: 补缺 | H13: S066 p.7 Table2 V43 | I13: AS_ehl2
A14: 中国 | B14: FDS-III | C14: 大半径 R | E14: 5.1 | F14: 补缺 | H14: S047 p.3 Table 1 | I14: AS_fdsiii
A15: 中国 | B15: FDS-III | C15: 小半径 a | E15: 1.7 | F15: 补缺 | H15: S047 p.3 Table 1 | I15: AS_fdsiii
A16: 中国 | B16: FDS-III | C16: 拉长比 κ | E16: 1.9 | F16: 补缺 | H16: S047 p.3 Table 1 | I16: AS_fdsiii
A17: 中国 | B17: FDS-III | C17: 三角度 δ | E17: 0.53 | F17: 补缺 | H17: S047 p.3 Table 1 | I17: AS_fdsiii
A18: 中国 | B18: FDS-III | C18: 总等离子体电流 Ip | E18: 16 | F18: 补缺 | H18: S047 p.3 Table 1 | I18: AS_fdsiii
A19: 中国 | B19: FY-1 | C19: 拉长比 κ | E19: 2.5 | F19: 补缺 | G19: S003 FY-1明确非圆等离子体a=10 cm、b=25 cm；κ=b/a=25/10=2.5，几何换算，非逐炮实测；δ不由非圆推定。 | H19: S003 FY-1条目，plasma a=10cm b=25cm，κ=b/a推算 | I19: AS_fy1
A20: 中国 | B20: HL-1 | C20: 拉长比 κ | E20: 1 | F20: 补缺 | G20: AS_S03已读取历史汇编将本装置明确归为圆形限制器/偏滤器配置；采用圆形等离子体理想边界：κ=b/a=1。是名义几何推算，不是逐炮平衡实测；原始装置论文尚待独立复核。 | H20: S003 HL-1条目：Circular Limiter/Divertor，理想边界几何推算 | I20: AS_hl1
A21: 中国 | B21: HL-1 | C21: 三角度 δ | E21: 0 | F21: 补缺 | G21: AS_S03已读取历史汇编将本装置明确归为圆形限制器/偏滤器配置；采用圆形等离子体理想边界：δ=0。是名义几何推算，不是逐炮平衡实测；原始装置论文尚待独立复核。 | H21: S003 HL-1条目：Circular Limiter/Divertor，理想边界几何推算 | I21: AS_hl1
A22: 中国 | B22: HL-1M | C22: 三角度 δ | E22: 0 | F22: 补缺 | G22: S060 原文明示圆形等离子体截面；按理想圆边界delta=0推算，非逐炮平衡实测。 | H22: S060 p.87 Abstract and §1（理想几何推算） | I22: AS_hl1m
A23: 中国 | B23: HL-2A | C23: 大半径 R | D23: 1.65 | E23: 1.64 | F23: 重核／版本调整 | H23: S050 p.1898 Table 1 Fig.1(a)列 | I23: AS_hl2a
A24: 中国 | B24: HL-2A | C24: 拉长比 κ | E24: 1 | F24: 补缺 | H24: S050 p.1898 Table 1 Fig.1(a)列 | I24: AS_hl2a
A25: 中国 | B25: HL-2A | C25: 三角度 δ | E25: 0 | F25: 补缺 | H25: S050 p.1898 Table 1 Fig.1(a)列 | I25: AS_hl2a
A26: 中国 | B26: HL-2M / HL-3（2012设计参数） | C26: 拉长比 κ | E26: 2 | F26: 补缺 | H26: S046 p.1 Table 1 | I26: AS_hl2m
A27: 中国 | B27: HL-2M / HL-3（2012设计参数） | C27: 三角度 δ | E27: ≥0.5 | F27: 补缺 | H27: S046 p.1 Table 1 | I27: AS_hl2m
A28: 中国 | B28: HL-2M / HL-3（2012设计参数） | C28: 总等离子体电流 Ip | D28: 3 | E28: 2.5 | F28: 重核／版本调整 | H28: S046 p.1 Table 1 | I28: AS_hl2m
A29: 中国 | B29: HT-6B | C29: 拉长比 κ | E29: 1 | F29: 补缺 | G29: AS_S03已读取历史汇编将本装置明确归为圆形限制器/偏滤器配置；采用圆形等离子体理想边界：κ=b/a=1。是名义几何推算，不是逐炮平衡实测；原始装置论文尚待独立复核。 | H29: S003 HT-6B条目：Circular Limiter/Divertor，理想边界几何推算 | I29: AS_ht6b
A30: 中国 | B30: HT-6B | C30: 三角度 δ | E30: 0 | F30: 补缺 | G30: AS_S03已读取历史汇编将本装置明确归为圆形限制器/偏滤器配置；采用圆形等离子体理想边界：δ=0。是名义几何推算，不是逐炮平衡实测；原始装置论文尚待独立复核。 | H30: S003 HT-6B条目：Circular Limiter/Divertor，理想边界几何推算 | I30: AS_ht6b
A31: 中国 | B31: HT-6M | C31: 三角度 δ | E31: 0 | F31: 补缺 | G31: AS_S03已读取历史汇编将本装置明确归为圆形限制器/偏滤器配置；采用圆形等离子体理想边界：δ=0。是名义几何推算，不是逐炮平衡实测；原始装置论文尚待独立复核。 | H31: S003 HT-6M条目：Circular Limiter/Divertor，理想边界几何推算 | I31: AS_ht6m
A32: 中国 | B32: HT-7 | C32: 三角度 δ | E32: 0 | F32: 补缺 | G32: AS_S03已读取历史汇编将本装置明确归为圆形限制器/偏滤器配置；采用圆形等离子体理想边界：δ=0。是名义几何推算，不是逐炮平衡实测；原始装置论文尚待独立复核。 | H32: S003 HT-7条目：Circular Limiter/Divertor，理想边界几何推算 | I32: AS_ht7
A33: 中国 | B33: KT-5 | C33: 大半径 R | E33: 0.3 | F33: 补缺 | H33: S062 p.71；原《核聚变与等离子体物理》7(1),27–30,1987 | I33: AS_kt5
A34: 中国 | B34: KT-5 | C34: 小半径 a | E34: 0.045 | F34: 补缺 | H34: S062 p.71；原《核聚变与等离子体物理》7(1),27–30,1987 | I34: AS_kt5
A35: 中国 | B35: KT-5 | C35: 总等离子体电流 Ip | E35: >0.005 | F35: 补缺 | H35: S062 p.71；原《核聚变与等离子体物理》7(1),27–30,1987 | I35: AS_kt5
A36: 中国 | B36: KT-5C | C36: 三角度 δ | E36: 0 | F36: 补缺 | G36: AS_S03已读取历史汇编将本装置明确归为圆形限制器/偏滤器配置；采用圆形等离子体理想边界：δ=0。是名义几何推算，不是逐炮平衡实测；原始装置论文尚待独立复核。 | H36: S003 KT-5C条目：Circular Limiter/Divertor，理想边界几何推算 | I36: AS_kt5c
A37: 中国 | B37: SUNIST-2 | C37: 大半径 R | D37: 0.525 | E37: 0.53 | F37: 重核／版本调整 | H37: S044 p.1 §2 | I37: AS_sunist2
A38: 中国 | B38: SUNIST-2 | C38: 小半径 a | D38: 0.325 | E38: 0.33 | F38: 重核／版本调整 | H38: S044 p.1 §2 | I38: AS_sunist2
A39: 中国 | B39: SUNIST-2 | C39: 拉长比 κ | E39: 2 | F39: 补缺 | H39: S044 p.1 §2 | I39: AS_sunist2
A40: 中国 | B40: SUNIST-2 | C40: 三角度 δ | E40: −0.6–0.6 | F40: 补缺 | H40: S044 p.1 §2 | I40: AS_sunist2
A41: 日本 | B41: C-TOKASTAR | C41: 大半径 R | E41: 约0.02 | F41: 补缺 | H41: S056 p.1047 §3-1 | I41: AS_ctokastar
A42: 日本 | B42: CREST | C42: 小半径 a | D42: 1.6 | E42: 1.5882353 | F42: 重核／版本调整 | G42: S049 slide 7：R=5.4 m，A=3.4；a=R/A=1.5882352941 m，几何换算，非实测。 | H42: S049 slide 7（几何推算） | I42: AS_crest
...

Sheet 调研说明
A1: 调研说明 · 范围、统计与使用口径
A2: 公开资料普查 · 检索截止 2026年9月9日 · 设计值与实验值分列保留
A5: 统计口径 | C5: 记录数包含设计修订、升级阶段和实验工况；不能直接当作独立物理装置数量。
A6: 参数单位 | C6: R、a采用m；κ和δ无量纲；Ip采用MA，为总环向等离子体电流。
A7: 缺失与推算 | C7: 空白表示未报告或冲突未解决。橙底及†标几何推算：同版a=R/A，明示圆形等离子体κ=1、δ=0；逐字段保留依据。
A8: 几何定义 | C8: 95%磁面、分离面、限制器与真空室尺寸分别说明；比较前查看逐字段注释。
A9: 数据性质 | C9: 文献直接报告含设计、额定能力、参考放电和历史汇编数字；推算非实测，五项有值不等于同时达到。
A10: 证据层级 | C10: 优先原始论文和官方资料；历史汇编、摘要与仅检索摘要均显式标记，不能等同全文核验。
A11: 地区与状态 | C11: 按所在地／研发国家归组；拟建地未明则标注。旧文献“运行”状态仅截至其证据年份。
A12: 覆盖边界 | C12: 纳入常规、球形及明确托卡马克模式；排除只有简单磁化环证据的TORIX。候选在缺失表保留。
A13: 完整性限制 | C13: 公开资料尚不能证明已穷尽所有装置和设计。早期形状参数、未公开方案和部分历史概念仍有缺口。
A16: 指标 | B16: 条数 | D16: 国家／地区 | E16: 记录数 | F16: 五项有值 | H16: 证据层级 | I16: 记录数
A17: 全部参数记录 | B17: =COUNTA(装置总览!B6:B315) -> 310 | D17: 中国 | E17: 28 | F17: 20 | H17: 仅检索摘要 | I17: 40
A18: 至少一项有值 | B18: =COUNTIF(装置总览!L6:L315,">0") -> 0 | D18: 中国台湾 | E18: 1 | F18: 0 | H18: 全文核验 | I18: 181
A19: 五项均有值 | B19: =COUNTIF(装置总览!L6:L315,5) -> 0 | D19: 日本 | E19: 51 | F19: 20 | H19: 仅名录 | I19: 2
A20: 大半径缺失 | B20: =COUNTBLANK(装置总览!C6:C315) -> 8 | D20: 韩国 | E20: 9 | F20: 6 | H20: 历史汇编待原文复核 | I20: 54
A21: 小半径缺失 | B21: =COUNTBLANK(装置总览!D6:D315) -> 19 | D21: 印度 | E21: 8 | F21: 6 | H21: 官方页面核验 | I21: 11
A22: 拉长比缺失 | B22: =COUNTBLANK(装置总览!E6:E315) -> 62 | D22: 泰国 | E22: 1 | F22: 1 | H22: 摘要核验 | I22: 14
A23: 三角度缺失 | B23: =COUNTBLANK(装置总览!F6:F315) -> 101 | D23: 巴基斯坦 | E23: 6 | F23: 0 | H23: 摘要及引言核验 | I23: 1
A24: 电流缺失 | B24: =COUNTBLANK(装置总览!G6:G315) -> 21 | D24: 伊朗 | E24: 4 | F24: 3 | H24: 目录全文／形状仅检索摘要 | I24: 1
D25: 哈萨克斯坦 | E25: 1 | F25: 1 | H25: 参数全文核验；状态见对应来源 | I25: 2
D26: 吉尔吉斯斯坦 | E26: 1 | F26: 1 | H26: 参数全文核验；形状仅检索摘要 | I26: 1
A27: 本轮补缺统计 | B27: 条数 | D27: 俄罗斯 | E27: 48 | F27: 38 | H27: 历史汇编／官方追述 | I27: 1
A28: 原有空格补入 | B28: 294 | D28: 格鲁吉亚（苏呼米／阿布哈兹） | E28: 1 | F28: 1 | H28: 全文及原图核验 | I28: 1
A29: 其中直接报告 | B29: 99 | D29: 英国 | E29: 16 | F29: 13 | H29: 原始论文首页预览及资料交叉 | I29: 1
A30: 其中几何推算 | B30: 195 | D30: 法国 | E30: 9 | F30: 9
A31: 全部直接齐全 | B31: 89 | D31: 德国 | E31: 6 | F31: 6
A32: 含推算的齐全 | B32: 114 | D32: 意大利 | E32: 11 | F32: 9
A33: 上一版五项齐全 | B33: 57 | D33: 瑞士 | E33: 2 | F33: 2
A34: 新增设计版本 | B34: 4 | D34: 捷克 | E34: 4 | F34: 4
D35: 西班牙 | E35: 2 | F35: 2
D36: 葡萄牙 | E36: 1 | F36: 1
D37: 荷兰 | E37: 2 | F37: 2
D38: 比利时 | E38: 1 | F38: 1
D39: 丹麦 | E39: 2 | F39: 1
D40: 匈牙利 | E40: 2 | F40: 2
D41: 卢森堡／美国（合作设计） | E41: 1 | F41: 1
D42: 欧洲（国际设计） | E42: 6 | F42: 6
D43: 土耳其 | E43: 1 | F43: 0
D44: 美国 | E44: 66 | F44: 37
...
